Workbook

Sheet Ref
A1: STATUS | B1: Sector | C1: WTR/NTR | D1: COC | F1: Private | G1: Public | I1: Reasons for Program Closure
A2: WTR | B2: Agriculture, Forestry and Fishery | C2: Agricultural Crops Production NC I | D2: Support Agronomic Crop Work Leading to Agricultural Crop Production NC I | F2: TVI | G2: TTI | I2: Due for Migration
A3: WTR | B3: Agriculture, Forestry and Fishery | C3: Agricultural Crops Production NC I | D3: Support Horticultural Crop Work Leading to Agricultural Crops Production NC I | F3: Farm School | G3: LGU | I3: No enrollees
A4: WTR | B4: Agriculture, Forestry and Fishery | C4: Agricultural Crops Production NC I | D4: Support Nursery Work Leading to Agricultural Crop Production NC I | F4: HEI | G4: SUC | I4: No trainings conducted since registration or for the past 2 years
A5: WTR | B5: Agriculture, Forestry and Fishery | C5: Agricultural Crops Production NC I | D5: Not in the list (use the remarks column for the title) | F5: NGO | G5: NGA | I5: Non-migration to updated TR
A6: WTR | B6: Agriculture, Forestry and Fishery | C6: Agricultural Crops Production NC II | D6: Care and Maintain Crops Leading to Agricultural Crops Production NC II | F6: Enterprise | G6: LUC | I6: Transfer of location without re-registration
A7: WTR | B7: Agriculture, Forestry and Fishery | C7: Agricultural Crops Production NC II | D7: Carry-out Harvest and Post-Harvest Operations Leading to Agricultural Crops Production NC II | I7: No qualified trainer
A8: WTR | B8: Agriculture, Forestry and Fishery | C8: Agricultural Crops Production NC II | D8: Control Weeds Leading to Agricultural Crops Production NC II | I8: Non-closure of compliance audit findings
A9: WTR | B9: Agriculture, Forestry and Fishery | C9: Agricultural Crops Production NC II | D9: Perform Nursery Operations Leading to Agricultural Crops Production NC II | I9: No scholarship allocation
A10: WTR | B10: Agriculture, Forestry and Fishery | C10: Agricultural Crops Production NC II | D10: Plant Crops Leading to Agricultural Crops Production NC II | I10: Financial Constraints
A11: WTR | B11: Agriculture, Forestry and Fishery | C11: Agricultural Crops Production NC II | D11: Not in the list (use the remarks column for the title) | I11: TVI cannot be located
A12: WTR | B12: Agriculture, Forestry and Fishery | C12: Agricultural Crops Production NC III | D12: Control Weeds Leading to Agricultural Crops Production NC III | I12: Closed TVI
A13: WTR | B13: Agriculture, Forestry and Fishery | C13: Agricultural Crops Production NC III | D13: Establish Agronomic Crops Leading to Agricultural Crops Production NC III | I13: Management Decision/ Change Focus
A14: WTR | B14: Agriculture, Forestry and Fishery | C14: Agricultural Crops Production NC III | D14: Implement Plant Nutrition Program leading to Agricultural Crops Production NC III | I14: Implementation of TC
A15: WTR | B15: Agriculture, Forestry and Fishery | C15: Agricultural Crops Production NC III | D15: Implement Post-Harest Program Leading to Agricultural Crops Production NC III | G15: January | H15: Lone | J15: New TVI & Program
A16: WTR | B16: Agriculture, Forestry and Fishery | C16: Agricultural Crops Production NC III | D16: Implement Vertebrate Pest Control Program Leading to Agricultural Crops Production NC III | G16: February | H16: Cebu City | J16: Additional Program
A17: WTR | B17: Agriculture, Forestry and Fishery | C17: Agricultural Crops Production NC III | D17: Keep Records for Farm Business Leading to Agricultural Crops Production NC III | G17: March | H17: 1st | J17: Migration
A18: WTR | B18: Agriculture, Forestry and Fishery | C18: Agricultural Crops Production NC III | D18: Prepare Land for Agricultural Crop Production Leading to Agricultural Crop Production NC III | G18: April | H18: 2nd | J18: Re-registration
A19: WTR | B19: Agriculture, Forestry and Fishery | C19: Agricultural Crops Production NC III | D19: Produce Organic Fertilizers Leading to Agricultural Crops Production NC III | G19: May | H19: 3rd | J19: Reissuance
A20: WTR | B20: Agriculture, Forestry and Fishery | C20: Agricultural Crops Production NC III | D20: Save, Prepare and Store Agricultural Seeds Leading to Agricultural Crops Production NC III | G20: June | H20: 4th | J20: Reissued CTPR
A21: WTR | B21: Agriculture, Forestry and Fishery | C21: Agricultural Crops Production NC III | D21: Undertake Agronomic Crop Harvesting Activities Leading to Agricultural Crops Production NC III | G21: July | H21: 5th | J21: CLOSED
A22: WTR | B22: Agriculture, Forestry and Fishery | C22: Agricultural Crops Production NC III | D22: Not in the list (use the remarks column for the title) | G22: August | H22: 6th | J22: Correction
A23: WTR | B23: Agriculture, Forestry and Fishery | C23: Agricultural Machinery Operation NC II | G23: September | H23: 7th | J23: Migrated
A24: WTR | B24: Agriculture, Forestry and Fishery | C24: Agricultural Machinery Servicing (4-Wheel Tractor) NC III | G24: October | H24: 8th | J24: Recognized
A25: WTR | B25: Agriculture, Forestry and Fishery | C25: Agroentrepreneurship NC II | G25: November | H25: 9th
A26: WTR | B26: Agriculture, Forestry and Fishery | C26: Agroentrepreneurship NC III | G26: December | H26: 10th
A27: WTR | B27: Agriculture, Forestry and Fishery | C27: Agroentrepreneurship NC IV | H27: North
A28: WTR | B28: Agriculture, Forestry and Fishery | C28: Animal Health Care and Management NC III | H28: South
A29: WTR | B29: Agriculture, Forestry and Fishery | C29: Animal Production (Poultry-Chicken) NC II | D29: Brood and Grow Chicks Leading to Animal Production (Poultry-Chicken) NC II
A30: WTR | B30: Agriculture, Forestry and Fishery | C30: Animal Production (Poultry-Chicken) NC II | D30: Maintain Poultry house Leading to Animal Production (Poultry-Chicken) NC II
A31: WTR | B31: Agriculture, Forestry and Fishery | C31: Animal Production (Poultry-Chicken) NC II | D31: Perform Pre-Lay and Lay Activities Leading to Animal Production (Poultry-Chicken) NC II
A32: WTR | B32: Agriculture, Forestry and Fishery | C32: Animal Production (Poultry-Chicken) NC II | D32: Trim Beak Leading to Animal Production (Poultry-Chicken) NC II
A33: WTR | B33: Agriculture, Forestry and Fishery | C33: Animal Production (Poultry-Chicken) NC II | D33: Not in the list (use the remarks column for the title)
A34: WTR | B34: Agriculture, Forestry and Fishery | C34: Animal Production (Ruminants) NC II | D34: Maintain Housing, Farm Implements and Surrounding Area Leading to Animal Production (Ruminants) NC II
A35: WTR | B35: Agriculture, Forestry and Fishery | C35: Animal Production (Ruminants) NC II | D35: Perform Breeding of Ruminants Leading to Animal Production (Ruminants) NC II
A36: WTR | B36: Agriculture, Forestry and Fishery | C36: Animal Production (Ruminants) NC II | D36: Provide Forage Leading to Animal Production (Ruminants) NC II
A37: WTR | B37: Agriculture, Forestry and Fishery | C37: Animal Production (Ruminants) NC II | D37: Raise Dairy Animals Leading to Animal Production (Ruminants) NC II
A38: WTR | B38: Agriculture, Forestry and Fishery | C38: Animal Production (Ruminants) NC II | D38: Raise Meat Type Animals Leading to Animal Production (Ruminants) NC II
A39: WTR | B39: Agriculture, Forestry and Fishery | C39: Animal Production (Ruminants) NC II | D39: Not in the list (use the remarks column for the title)
A40: WTR | B40: Agriculture, Forestry and Fishery | C40: Animal Production (Swine) NC II | D40: Apply Bio-diversity Measures Leading to Animal Production (Swine) NC II
...

Sheet Ref2
A1: Agriculture, Forestry and Fishery | B1: Automotive and Land Transportation | C1: Chemicals/ Plastics/ Petrochemicals | D1: Construction | E1: Creative Sector | F1: Decorative Crafts | G1: Electrical and Electronics | H1: Footwear and Leathergoods | I1: Furniture and Fixtures | J1: Garments | K1: Heating, Ventilation, Airconditioning and Refrigeration | L1: Human Health/ Health Care | M1: Information and Communication Technology | N1: Logistics | O1: Maritime | P1: Metals and Engineering | Q1: Others (Languages) | R1: Processed Food and Beverages | S1: Pyrotechnics | T1: Social, Community Development and Other Services | U1: Tourism | V1: TVET | W1: Utilities | X1: Visual Arts | Y1: Wholesale and Retail Trading
A2: Agricultural Crops Production NC I | B2: Auto Engine Rebuilding NC II | C2: Chemical Process Operations NC III | D2: Carpentry NC II | E2: Audio Production Services NC I | F2: Jewelry Making (Fine Jewelry) NC II | G2: Computer Systems Servicing NC II | H2: Shoemaking NC I | I2: Furniture Making (Finishing) NC II | J2: Dressmaking NC II | K2: Air Duct Servicing NC II | L2: Assistive Rehabilitation Technology Services (Orthotics) NC II | M2: 2D Animation NC III | N2: Multimodal Transport Operations and Logistics (Seafreight Import) Services NC II | O2: Marine Electricity NC II | P2: 5-Axis CNC Machine Operation NC III | R2: Fish Products Packaging NC II | S2: Pyrotechnics NC II | T2: Barbering NC II | U2: Attractions and Theme Parks Operations NC II | V2: Trainers Methodology Level I (In-Company Trainer) | W2: Diesel Power Plant Maintenance NC III | X2: Illustration NC II | Y2: Customer Services NC II
A3: Agricultural Crops Production NC I - Mobile Training Program | B3: Auto Engine Rebuilding NC II - Mobile Training Program | C3: Chemical Process Operations NC III - Mobile Training Program | D3: Carpentry NC II - Mobile Training Program | E3: Audio Production Services NC I - Mobile Training Program | F3: Jewelry Making (Fine Jewelry) NC II - Mobile Training Program | G3: Computer Systems Servicing NC II - Mobile Training Program | H3: Shoemaking NC I - Mobile Training Program | I3: Furniture Making (Finishing) NC II - Mobile Training Program | J3: Dressmaking NC II - Mobile Training Program | K3: Air Duct Servicing NC II - Mobile Training Program | L3: Assistive Rehabilitation Technology Services (Orthotics) NC II - Mobile Training Program | M3: 2D Animation NC III - Mobile Training Program | N3: Multimodal Transport Operations and Logistics (Seafreight Import) Services NC II - Mobile Training Program | O3: Marine Electricity NC II - Mobile Training Program | P3: 5-Axis CNC Machine Operation NC III - Mobile Training Program | R3: Fish Products Packaging NC II - Mobile Training Program | S3: Pyrotechnics NC II - Mobile Training Program | T3: Barbering NC II - Mobile Training Program | U3: Attractions and Theme Parks Operations NC II - Mobile Training Program | V3: Trainers Methodology Level I (In-Company Trainer) - Mobile Training Program | W3: Diesel Power Plant Maintenance NC III - Mobile Training Program | X3: Illustration NC II - Mobile Training Program | Y3: Customer Services NC II - Mobile Training Program
A4: Agricultural Crops Production NC II | B4: Automotive Body Painting/Finishing NC I | D4: Carpentry NC III | E4: Film and Video Postproduction NC III | F4: Jewelry Making (Fine Jewelry) NC III | G4: Consumer Electronics Servicing NC III | H4: Shoemaking NC II | J4: Fashion Design (Apparel) NC III | K4: Commercial Air-conditioning Installation and Servicing NC III | L4: Assistive Rehabilitation Technology Services (Prosthetics) NC II | M4: 2D Game Art Development NC III | N4: Multimodal Transport Operations and Logistics (Seafreight Import) Services NC III | O4: Ship's Catering Services NC I | P4: CAD/CAM Operation NC III | R4: Food Processing NC I | T4: Beauty Care (Nail Care) Services NC II | U4: Barista NC II | V4: Trainers Methodology Level I (Trainer/Assessor) | W4: Diesel Power Plant Operation and Maintenance NC II | X4: Photography NC II
A5: Agricultural Crops Production NC II - Mobile Training Program | B5: Automotive Body Painting/Finishing NC III | D5: Carpentry NC III - Mobile Training Program | E5: Film and Video Postproduction NC III - Mobile Training Program | F5: Jewelry Making (Fine Jewelry) NC III - Mobile Training Program | G5: Consumer Electronics Servicing NC III - Mobile Training Program | H5: Shoemaking NC II - Mobile Training Program | J5: Fashion Design (Apparel) NC III - Mobile Training Program | K5: Commercial Air-conditioning Installation and Servicing NC III - Mobile Training Program | L5: Assistive Rehabilitation Technology Services (Prosthetics) NC II - Mobile Training Program | M5: 2D Game Art Development NC III - Mobile Training Program | N5: Multimodal Transport Operations and Logistics (Seafreight Import) Services NC III - Mobile Training Program | O5: Ship's Catering Services NC I - Mobile Training Program | P5: CAD/CAM Operation NC III - Mobile Training Program | R5: Food Processing NC I - Mobile Training Program | T5: Beauty Care (Nail Care) Services NC II - Mobile Training Program | U5: Barista NC II - Mobile Training Program | V5: Trainers Methodology Level I (Trainer/Assessor) - Mobile Training Program | W5: Diesel Power Plant Operation and Maintenance NC II - Mobile Training Program | X5: Photography NC II - Mobile Training Program
A6: Agricultural Crops Production NC III | B6: Automotive Body Painting/Finishing NC III - Mobile Training Program | D6: Construction Lift Passenger/Material Elevator Operation NC II | E6: Handloom Weaving (Upright) NC II | G6: Consumer Electronics Servicing NC IV | J6: Tailoring NC II | K6: Commercial Refrigeration Installation and Servicing NC III | L6: Assistive Rehabilitation Technology Services (Wheelchair) NC II | M6: 3D Animation NC III | N6: Multimodal Transport Operations and Logistics (Seafreight Import) Services NC IV | O6: Ships' Catering NC III (Ships' Cooks) | P6: CNC Electric Discharge Machine (EDM) Wire Cut Operation NC III | R6: Food Processing NC II | T6: Beauty Care (Nail Enhancement Technology) Services NC III | U6: Bartending NC II | V6: Trainers Methodology Level II (Training Designer/Developer) | W6: Diesel Power Plant Operation and Maintenance NC III
A7: Agricultural Crops Production NC III - Mobile Training Program | B7: Automotive Body Repairing NC II | D7: Construction Lift Passenger/Material Elevator Operation NC II - Mobile Training Program | E7: Handloom Weaving (Upright) NC II - Mobile Training Program | G7: Consumer Electronics Servicing NC IV - Mobile Training Program | J7: Tailoring NC II - Mobile Training Program | K7: Commercial Refrigeration Installation and Servicing NC III - Mobile Training Program | L7: Assistive Rehabilitation Technology Services (Wheelchair) NC II - Mobile Training Program | M7: 3D Animation NC III - Mobile Training Program | N7: Multimodal Transport Operations and Logistics (Seafreight Import) Services NC IV - Mobile Training Program | O7: Ships' Catering NC III (Ships' Cooks) - Mobile Training Program | P7: CNC Electric Discharge Machine (EDM) Wire Cut Operation NC III - Mobile Training Program | R7: Food Processing NC II - Mobile Training Program | T7: Beauty Care (Nail Enhancement Technology) Services NC III - Mobile Training Program | U7: Bartending NC II - Mobile Training Program | V7: Trainers Methodology Level II (Training Designer/Developer) - Mobile Training Program | W7: Diesel Power Plant Operation and Maintenance NC III - Mobile Training Program
A8: Agricultural Machinery Operation NC II | B8: Automotive Body Repairing NC II - Mobile Training Program | D8: Construction Painting NC II | E8: Beadwork Accessories and Diversified Beadwork Products Making NC II | G8: Biomedical Equipment Servicing NC II | K8: Ice Plant Refrigeration Servicing NC III | L8: Barangay Health Services NC II | M8: 3D Game Art Development NC III | N8: Warehousing Services NC II | P8: CNC Lathe Machine Operation NC II | R8: Food Processing NC III | T8: Beauty Care (Skin Care) Services NC II | U8: Bread and Pastry Production NC II | V8: Develop Learning Materials for E-Learning leading to Trainer Methodology Level II | W8: Electric Power Distribution Line Construction NC II
A9: Agricultural Machinery Operation NC II - Mobile Training Program | B9: Automotive Electrical Assembly NC II | D9: Construction Painting NC II - Mobile Training Program | E9: Beadwork Accessories and Diversified Beadwork Products Making NC II - Mobile Training Program | G9: Biomedical Equipment Servicing NC II - Mobile Training Program | K9: Ice Plant Refrigeration Servicing NC III - Mobile Training Program | L9: Barangay Health Services NC II - Mobile Training Program | M9: 3D Game Art Development NC III - Mobile Training Program | N9: Warehousing Services NC II - Mobile Training Program | P9: CNC Lathe Machine Operation NC II - Mobile Training Program | R9: Food Processing NC III - Mobile Training Program | T9: Beauty Care (Skin Care) Services NC II - Mobile Training Program | U9: Bread and Pastry Production NC II - Mobile Training Program | V9: Develop Learning Materials for E-Learning leading to Trainer Methodology Level II - Mobile Training Program | W9: Electric Power Distribution Line Construction NC II - Mobile Training Program
A10: Agricultural Machinery Servicing (4-Wheel Tractor) NC III | B10: Automotive Electrical Assembly NC II - Mobile Training Program | D10: Construction Painting NC III | E10: Handloom Weaving (Backstrap) NC II | G10: Electrical Installation and Maintenance NC II | K10: Land-Based Transport Mobile Air-conditioning (MAC) NC II | L10: Biomedical Equipment Servicing NC II (Superseded) | M10: Animation NC II | N10: Warehousing Services NC III | P10: CNC Lathe Machine Operation NC III | R10: Food Processing NC IV | T10: Beauty Care Services (Nail Care) NC III (Superseded) | U10: Commercial Cooking NC II (Amended) | V10: Develop Learning Materials Leading to Trainers Methodology Level II | W10: Electric Power Distribution Operation and Maintenance NC III
A11: Agricultural Machinery Servicing (4-Wheel Tractor) NC III - Mobile Training Program | B11: Automotive Electrical Assembly NC III | D11: Construction Painting NC III - Mobile Training Program | E11: Handloom Weaving (Backstrap) NC II - Mobile Training Program | G11: Electrical Installation and Maintenance NC II - Mobile Training Program | K11: Land-Based Transport Mobile Air-conditioning (MAC) NC II - Mobile Training Program | L11: Biomedical Equipment Servicing NC II (Superseded) - Mobile Training Program | M11: Animation NC II - Mobile Training Program | N11: Warehousing Services NC III - Mobile Training Program | P11: CNC Lathe Machine Operation NC III - Mobile Training Program | R11: Food Processing NC IV - Mobile Training Program | T11: Bookkeeping NC III | U11: Commercial Cooking NC II (Amended) - Mobile Training Program | V11: Develop Learning Materials Leading to Trainers Methodology Level II - Mobile Training Program | W11: Electric Power Distribution Operation and Maintenance NC III - Mobile Training Program
A12: Agroentrepreneurship NC II | B12: Automotive Electrical Assembly NC III - Mobile Training Program | D12: Heavy Equipment Operation (Articulated Off-Highway Dump Truck) NC II | E12: Paper Mache Making NC II | G12: Electrical Installation and Maintenance NC III | K12: Land-based Transport Refrigeration Servicing NC II | L12: Caregiving (Clients with Special Needs) NC II | M12: Broadband Installation (Fixed Wireless Systems) NC II | N12: Warehousing Services NC IV | P12: CNC Milling Machine Operation NC II | R12: Slaughtering Operations (Large Animal) NC II | T12: Bookkeeping NC III - Mobile Training Program | U12: Commercial Cooking NC III (Superseded) | V12: Develop Training Curriculum, Develop Training Materials, Develop Competency Assessment Tools Leading to Trainers Methodology Level II | W12: Electric Power Distribution Operation and Maintenance NC IV
A13: Agroentrepreneurship NC II - Mobile Training Program | B13: Automotive Mechanical Assembly NC II | D13: Heavy Equipment Operation (Articulated Off-Highway Dump Truck) NC II - Mobile Training Program | E13: Paper Mache Making NC II - Mobile Training Program | G13: Electrical Installation and Maintenance NC III - Mobile Training Program | K13: Land-based Transport Refrigeration Servicing NC II - Mobile Training Program | L13: Caregiving (Clients with Special Needs) NC II - Mobile Training Program | M13: Broadband Installation (Fixed Wireless Systems) NC II - Mobile Training Program | N13: Warehousing Services NC IV - Mobile Training Program | P13: CNC Milling Machine Operation NC II - Mobile Training Program | R13: Slaughtering Operations (Large Animal) NC II - Mobile Training Program | T13: Domestic Work NC II | U13: Commercial Cooking NC III (Superseded) - Mobile Training Program | V13: Develop Training Curriculum, Develop Training Materials, Develop Competency Assessment Tools Leading to Trainers Methodology Level II - Mobile Training Program | W13: Electric Power Distribution Operation and Maintenance NC IV - Mobile Training Program
A14: Agroentrepreneurship NC III | B14: Automotive Mechanical Assembly NC II - Mobile Training Program | D14: Heavy Equipment Operation (Backhoe Loader) NC II | E14: Head Embroidery NC II | G14: Electrical Installation and Maintenance NC IV | K14: RAC Servicing (DomRAC) NC II | L14: Caregiving (Elderly) NC II | M14: Cable TV Installation NC II | P14: CNC Milling Machine Operation NC III | R14: Slaughtering Operations (Swine) NC II | T14: Domestic Work NC II - Mobile Training Program | U14: Commercial Cooking NC IV (Superseded) | V14: Online Program for Developing Training Curriculum Leading to Trainers Methodology Level II | W14: Garbage Collection NC I
A15: Agroentrepreneurship NC III - Mobile Training Program | B15: Automotive Mechanical Assembly NC III | D15: Heavy Equipment Operation (Backhoe Loader) NC II - Mobile Training Program | E15: Head Embroidery NC II - Mobile Training Program | G15: Electrical Installation and Maintenance NC IV - Mobile Training Program | K15: RAC Servicing (DomRAC) NC II - Mobile Training Program | L15: Caregiving (Elderly) NC II - Mobile Training Program | M15: Cable TV Installation NC II - Mobile Training Program | P15: CNC Milling Machine Operation NC III - Mobile Training Program | R15: Slaughtering Operations (Swine) NC II - Mobile Training Program | T15: Hairdressing NC II | U15: Cookery NC II | V15: Online Program for Developing Training Curriculum Leading to Trainers Methodology Level II - Mobile Training Program | W15: Garbage Collection NC I - Mobile Training Program
A16: Agroentrepreneurship NC IV | B16: Automotive Mechanical Assembly NC III - Mobile Training Program | D16: Heavy Equipment Operation (Bulldozer) NC II | E16: Mat Weaving and Diversified Mat Products Making NC II | G16: Electronic Products Assembly and Servicing NC II | K16: RAC Servicing (PACU-CRE) NC III (Amended) | L16: Caregiving (Grade Schooler to Adolescent) NC II | M16: Cable TV Operation and Maintenance NC III | P16: Die Designing NC IV | R16: Process Food by Fermentation and Pickling leading to Food Processing NC II | T16: Hairdressing NC II - Mobile Training Program | U16: Cookery NC II - Mobile Training Program | W16: Line Construction (Electric Power Distribution) NC II (Amended)
A17: Agroentrepreneurship NC IV - Mobile Training Program | B17: Automotive Painting NC II | D17: Heavy Equipment Operation (Bulldozer) NC II - Mobile Training Program | E17: Mat Weaving and Diversified Mat Products Making NC II - Mobile Training Program | G17: Electronic Products Assembly and Servicing NC II - Mobile Training Program | K17: RAC Servicing (PACU-CRE) NC III (Amended) - Mobile Training Program | L17: Caregiving (Grade Schooler to Adolescent) NC II - Mobile Training Program | M17: Cable TV Operation and Maintenance NC III - Mobile Training Program | P17: Die Designing NC IV - Mobile Training Program | R17: Process Food by Fermentation and Pickling leading to Food Processing NC II - Mobile Training Program | T17: Hairdressing NC III | U17: Events Management Services NC III | W17: Sanitary Landfill Operations NC II
A18: Animal Health Care and Management NC III | B18: Automotive Painting NC II - Mobile Training Program | D18: Heavy Equipment Operation (Concrete Pump) NC II | E18: Wood Carving NC II | G18: Electronics Back-End Operation NC II | K18: Transport RAC Servicing NC II (Amended) | L18: Caregiving (Newborn to Pre-Schooler) NC II | M18: Contact Center Services NC II | P18: Electric Discharge Machine (EDM) Sinking Operation NC II | R18: Process Food by Sugar Concentration leading to Food Processing NC II | T18: Hairdressing NC III - Mobile Training Program | U18: Events Management Services NC III - Mobile Training Program | W18: Sanitary Landfill Operations NC II - Mobile Training Program
A19: Animal Health Care and Management NC III - Mobile Training Program | B19: Automotive Servicing (Chassis Repair) NC II | D19: Heavy Equipment Operation (Concrete Pump) NC II - Mobile Training Program | E19: Wood Carving NC II - Mobile Training Program | G19: Electronics Back-End Operation NC II - Mobile Training Program | K19: Transport RAC Servicing NC II (Amended) - Mobile Training Program | L19: Caregiving (Newborn to Pre-Schooler) NC II - Mobile Training Program | M19: Contact Center Services NC II - Mobile Training Program | P19: Electric Discharge Machine (EDM) Sinking Operation NC II - Mobile Training Program | R19: Process Food by Sugar Concentration leading to Food Processing NC II - Mobile Training Program | T19: Lifeguard Services NC II | U19: Food and Beverage Services NC II | W19: Sanitary Landfill Operations NC III
A20: Animal Production (Poultry-Chicken) NC II | B20: Automotive Servicing (Chassis Repair) NC II - Mobile Training Program | D20: Heavy Equipment Operation (Container Stacker) NC II | E20: Basket Weaving NC II | G20: Electronics Front-of-Line Operation NC II | L20: Caregiving NC II | M20: Game Programming NC III | P20: Flux-Cored Arc Welding (FCAW) NC I | R20: Process Food by Salting and Curing leading to Food Processing NC II | T20: Lifeguard Services NC II - Mobile Training Program | U20: Food and Beverage Services NC II - Mobile Training Program | W20: Sanitary Landfill Operations NC III - Mobile Training Program
A21: Animal Production (Poultry-Chicken) NC II - Mobile Training Program | B21: Automotive Servicing (Electrical Repair) NC II | D21: Heavy Equipment Operation (Container Stacker) NC II - Mobile Training Program | E21: Basket Weaving NC II - Mobile Training Program | G21: Electronics Front-of-Line Operation NC II - Mobile Training Program | L21: Caregiving NC II - Mobile Training Program | M21: Game Programming NC III - Mobile Training Program | P21: Flux-Cored Arc Welding (FCAW) NC I - Mobile Training Program | R21: Process Food by Salting and Curing leading to Food Processing NC II - Mobile Training Program | T21: Lifeguard Services NC III | U21: Food and Beverage Services NC III (Amended) | W21: Transmission Line Installation and Maintenance NC II
A22: Animal Production (Ruminants) NC II | B22: Automotive Servicing (Electrical Repair) NC II - Mobile Training Program | D22: Heavy Equipment Operation (Crawler Crane) NC III | E22: Lighting for Live Performances NC II | G22: Electronics/Semiconductor Production Line Machine Servicing NC III | L22: Contact Tracing NC II | M22: Medical Coding and Claims Processing NC III | P22: Flux-Cored Arc Welding (FCAW) NC II | R22: Process Food by Salting, Curing and Smoking Leading to Food Processing NC II | T22: Lifeguard Services NC III - Mobile Training Program | U22: Food and Beverage Services NC III (Amended) - Mobile Training Program | W22: Transmission Line Installation and Maintenance NC II - Mobile Training Program
A23: Animal Production (Ruminants) NC II - Mobile Training Program | B23: Automotive Servicing (Engine Repair) NC II | D23: Heavy Equipment Operation (Crawler Crane) NC III - Mobile Training Program | E23: Lighting for Live Performances NC II - Mobile Training Program | G23: Electronics/Semiconductor Production Line Machine Servicing NC III - Mobile Training Program | L23: Contact Tracing NC II - Mobile Training Program | M23: Medical Coding and Claims Processing NC III - Mobile Training Program | P23: Flux-Cored Arc Welding (FCAW) NC II - Mobile Training Program | R23: Process Food by Salting, Curing and Smoking Leading to Food Processing NC II - Mobile Training Program | T23: Microfinance Technology NC II | U23: Food and Beverage Services NC III | W23: Transmission Line Installation and Maintenance NC III
A24: Animal Production (Swine) NC II | B24: Automotive Servicing (Engine Repair) NC II - Mobile Training Program | D24: Heavy Equipment Operation (Forklift) NC II (Superseded) | G24: Hard Disk Drive (HDD) Front-of-line (FOL) Operations NC II | L24: Dental Hygiene Level IV | M24: Medical Transcription NC II | P24: Flux-Cored Arc Welding (FCAW) NC III | R24: Slaughtering Operations NC II (Amended) | T24: Microfinance Technology NC II - Mobile Training Program | U24: Food and Beverage Services NC III - Mobile Training Program | W24: Transmission Line Installation and Maintenance NC III - Mobile Training Program
A25: Animal Production (Swine) NC II - Mobile Training Program | B25: Automotive Servicing NC I | D25: Heavy Equipment Operation (Forklift) NC II (Superseded) - Mobile Training Program | G25: Hard Disk Drive (HDD) Front-of-line (FOL) Operations NC II - Mobile Training Program | L25: Dental Hygiene Level IV - Mobile Training Program | M25: Medical Transcription NC II - Mobile Training Program | P25: Flux-Cored Arc Welding (FCAW) NC III - Mobile Training Program | T25: Microfinance Technology NC IV | U25: Food and Beverage Services NC IV | W25: Transmission Line Installation and Maintenance NC IV
A26: Aquaculture NC II (Superseded) | B26: Automotive Servicing NC I - Mobile Training Program | D26: Heavy Equipment Operation (Forklift) NC II | G26: Instrumentation and Control Servicing NC II | L26: Dental Laboratory Technology Services (Fixed Dentures/Restorations) NC II | M26: Programming (.Net Technology) NC III | P26: Gas Metal Arc Welding (GMAW) NC I | T26: Microfinance Technology NC IV - Mobile Training Program | U26: Food and Beverage Services NC IV - Mobile Training Program | W26: Transmission Line Installation and Maintenance NC IV - Mobile Training Program
A27: Aquaculture NC II (Superseded) - Mobile Training Program | B27: Automotive Servicing NC III | D27: Heavy Equipment Operation (Forklift) NC II - Mobile Training Program | G27: Instrumentation and Control Servicing NC II - Mobile Training Program | L27: Dental Laboratory Technology Services (Fixed Dentures/Restorations) NC II - Mobile Training Program | M27: Programming (.Net Technology) NC III - Mobile Training Program | P27: Gas Metal Arc Welding (GMAW) NC I - Mobile Training Program | T27: Microinsurance Services (Mutual Benefit) NC II | U27: Food Production (Professional Cookery) NC III
A28: Aquaculture (Grow-out Operation) NC II | B28: Automotive Servicing NC III - Mobile Training Program | D28: Heavy Equipment Operation (Hydraulic Excavator) NC II | G28: Instrumentation and Control Servicing NC III | L28: Dental Laboratory Technology Services (Removable Dentures/Appliances) NC II | M28: Programming (Java) NC III | P28: Gas Metal Arc Welding (GMAW) NC II | T28: Microinsurance Services (Mutual Benefit) NC II - Mobile Training Program | U28: Food Production (Professional Cookery) NC III - Mobile Training Program
A29: Aquaculture (Grow-out Operation) NC II - Mobile Training Program | B29: Automotive Servicing NC IV | D29: Heavy Equipment Operation (Hydraulic Excavator) NC II - Mobile Training Program | G29: Instrumentation and Control Servicing NC III - Mobile Training Program | L29: Dental Laboratory Technology Services (Removable Dentures/Appliances) NC II - Mobile Training Program | M29: Programming (Java) NC III - Mobile Training Program | P29: Gas Metal Arc Welding (GMAW) NC II - Mobile Training Program | T29: Performing Arts (Ballroom Dancing) NC II | U29: Food Production (Professional Cookery) NC IV
A30: Aquaculture (Hatchery Operation) NC II | B30: Automotive Servicing NC IV - Mobile Training Program | D30: Heavy Equipment Operation (Motor Grader) NC II | G30: Instrumentation and Control Servicing NC IV | L30: Dental Laboratory Technology Services NC I | M30: Programming (Oracle Database) NC III | P30: Gas Metal Arc Welding (GMAW) NC III | T30: Performing Arts (Ballroom Dancing) NC II - Mobile Training Program | U30: Food Production (Professional Cookery) NC IV - Mobile Training Program
A31: Aquaculture (Hatchery Operation) NC II - Mobile Training Program | B31: Automotive Wiring Harness Assembly NC II | D31: Heavy Equipment Operation (Motor Grader) NC II - Mobile Training Program | G31: Instrumentation and Control Servicing NC IV - Mobile Training Program | L31: Dental Laboratory Technology Services NC I - Mobile Training Program | M31: Programming (Oracle Database) NC III - Mobile Training Program | P31: Gas Metal Arc Welding (GMAW) NC III - Mobile Training Program | T31: Performing Arts (Dance) NC II | U31: Front Office Services NC II
A32: Aquaculture (Tilapia Culture) NC II | B32: Automotive Wiring Harness Assembly NC II - Mobile Training Program | D32: Heavy Equipment Operation (Overhead and Gantry Crane) NC III | G32: Mechatronics Servicing NC II | L32: Dental Technology NC IV | M32: Telecom OSP and Subscriber Line Installation (Copper Cable/POTS and DSL) NC II | P32: Gas Tungsten Arc Welding (GTAW) NC II | T32: Performing Arts (Dance) NC II - Mobile Training Program | U32: Front Office Services NC II - Mobile Training Program
A33: Aquaculture (Tilapia Culture) NC II - Mobile Training Program | B33: Driving (Articulated Vehicle) NC III | D33: Heavy Equipment Operation (Overhead and Gantry Crane) NC III - Mobile Training Program | G33: Mechatronics Servicing NC II - Mobile Training Program | L33: Dental Technology NC IV - Mobile Training Program | M33: Telecom OSP and Subscriber Line Installation (Copper Cable/POTS and DSL) NC II - Mobile Training Program | P33: Gas Tungsten Arc Welding (GTAW) NC II - Mobile Training Program | T33: Performing Arts (Magician) NC II | U33: Front Office Services NC III
A34: Artificial Insemination (Large Ruminants) NC II | B34: Driving (Articulated Vehicle) NC III - Mobile Training Program | D34: Heavy Equipment Operation (Paver) NC II | G34: Mechatronics Servicing NC III | L34: Emergency Medical Services NC II | M34: Telecom OSP Installation (Fiber Optic Cable) NC II | P34: Gas Tungsten Arc Welding (GTAW) NC IV | T34: Performing Arts (Magician) NC II - Mobile Training Program | U34: Front Office Services NC III - Mobile Training Program
A35: Artificial Insemination (Large Ruminants) NC II - Mobile Training Program | B35: Driving (Passenger Bus/Straight Truck) NC III | D35: Heavy Equipment Operation (Paver) NC II - Mobile Training Program | G35: Mechatronics Servicing NC III - Mobile Training Program | L35: Emergency Medical Services NC II - Mobile Training Program | M35: Telecom OSP Installation (Fiber Optic Cable) NC II - Mobile Training Program | P35: Gas Tungsten Arc Welding (GTAW) NC IV - Mobile Training Program | T35: Performing Arts (Song) NC II | U35: Front Office Services NC IV
A36: Artificial Insemination (Swine) NC II | B36: Driving (Passenger Bus/Straight Truck) NC III - Mobile Training Program | D36: Heavy Equipment Operation (Rigid Off-Highway Dump Truck) NC II | G36: Mechatronics Servicing NC IV | L36: Emergency Medical Services NC III | M36: Visual Graphic Design NC III | P36: Gas Welding NC I | T36: Performing Arts (Song) NC II - Mobile Training Program | U36: Front Office Services NC IV - Mobile Training Program
A37: Artificial Insemination (Swine) NC II - Mobile Training Program | B37: Driving NC II | D37: Heavy Equipment Operation (Rigid Off-Highway Dump Truck) NC II - Mobile Training Program | G37: Mechatronics Servicing NC IV - Mobile Training Program | L37: Emergency Medical Services NC III - Mobile Training Program | M37: Visual Graphic Design NC III - Mobile Training Program | P37: Gas Welding NC I - Mobile Training Program | T37: Public Employment Services NC IV | U37: Housekeeping NC II
A38: Bamboo Processing (Engineered Bamboo) NC II | B38: Driving NC II - Mobile Training Program | D38: Heavy Equipment Operation (Rigid On-Highway Dump Truck) NC II | G38: Mobile Phones and Handheld Gadgets Servicing NC III | L38: Health Care Services NC II | M38: Web Development NC III | P38: Gas Welding NC II | T38: Public Employment Services NC IV - Mobile Training Program | U38: Housekeeping NC II - Mobile Training Program
... A40: Bamboo Production NC II | B40: Forging NC II - Mobile Training Program | D40: Heavy Equipment Operation (Road Roller) NC II | G40: Semiconductor Back-End Operation NC II | L40: Hilot (Wellness Massage) NC II | M40: Develop Responsive Web Design Leading to Web Development NC III | P40: Machining NC I | T40: Real Estate Services NC II - Mobile Training Program | U40: Housekeeping NC III - Mobile Training Program
A41: Bamboo Production NC II - Mobile Training Program | B41: Forging NC III | D41: Heavy Equipment Operation (Road Roller) NC II - Mobile Training Program | G41: Semiconductor Back-End Operation NC II - Mobile Training Program | L41: Hilot (Wellness Massage) NC II - Mobile Training Program | P41: Machining NC I - Mobile Training Program | T41: Security Services NC I | U41: Housekeeping NC IV
...

Sheet 2024 F08
A1: PROVINCE | B1: Name of TVI/Company (a) | C1: Qualification Title (b) | D1: Conducts Orientation on Program Registration (c) | E1: Conducts Site Inspection and Submitts Site Inspection Report (d) | F1: Reviews and Evaluates Program Registration Application Documents (Day 1) (e) | G1: Prepares Recommendation and Submits Complete Documents to RO (Day 2) (f) | H1: Transmits the Application Documents, and Recommendations to RO (1-2 days) (g) | I1: Approved/Disapproves Program Registration Application Documents and Issues/Transmits CTPR/Letter of Denial (Day 3) (h) | J1: Transmits the CTPR and Complete Documents to Provincial Office/TVIs and conducts Post Orientation (1-2 days) (i) | K1: TOTAL NUMBER OF DAYS (3 DAYS) | L1: RO REMARKS
A2: Cebu | B2: Don Bosco Technical Vocational Education & Training Center - Balamban, Inc. | C2: Electrical Installation and Maintenance NC II-MTP | D2: 45040 | E2: 45299 | F2: 45300 | G2: N/A | H2: N/A | I2: 45301 | J2: 45302
A3: Cebu | B3: Don Bosco Technical Vocational Education & Training Center - Balamban, Inc. | C3: Driving NC II-MTP | D3: 45040 | E3: 45299 | F3: 45300 | G3: N/A | H3: N/A | I3: 45301 | J3: 45302
A4: Cebu | B4: Don Bosco Technical Vocational Education & Training Center - Balamban, Inc. | C4: Shielded Metal Arc Welding (SMAW) NC I-MTP | D4: 45040 | E4: 45299 | F4: 45300 | G4: N/A | H4: N/A | I4: 45301 | J4: 45302
A5: Cebu | B5: Don Bosco Technical Vocational Education & Training Center - Balamban, Inc. | C5: Shielded Metal Arc Welding (SMAW) NC II-MTP | D5: 45040 | E5: 45299 | F5: 45300 | G5: N/A | H5: N/A | I5: 45301 | J5: 45302
A6: Cebu | B6: University of the Visayas, Inc. | C6: Hosuekeeping NC II-MTP | D6: 45040 | E6: 45267 | F6: 45301 | G6: N/A | H6: N/A | I6: 45302 | J6: 45303
A7: Cebu | B7: University of the Visayas, Inc. | C7: Food and Beverage Services NC II-MTP | D7: 45040 | E7: 45267 | F7: 45303 | G7: N/A | H7: N/A | I7: 45306 | J7: 45307
A8: Cebu | B8: Sto. Nino Skills Development and Assessment Center | C8: Hairdressing NC II-MTP | D8: 45030 | E8: 45306 | F8: 45308 | G8: N/A | H8: N/A | I8: 45309 | J8: 45310
A9: Cebu | B9: Sto. Nino Skills Development and Assessment Center | C9: Housekeeping NC II-MTP | D9: 45030 | E9: 45306 | F9: 45308 | G9: N/A | H9: N/A | I9: 45309 | J9: 45310
A10: Cebu | B10: 3A Prime Hospitality Trianing and Assessment Center Inc. | C10: Computer Systems Servicing NC II-MTP | D10: 45040 | E10: 45314 | F10: 45314 | G10: N/A | H10: N/A | I10: 45315 | J10: 45316
A11: Negros Oriental | B11: Sto. Nino Skills Training and Assessment Center | C11: Driving NC II-MTP | D11: 45040 | E11: 45308 | F11: 45316 | G11: N/A | H11: N/A | I11: 45317 | J11: 45320
A12: Cebu | B12: Primordial Training Center Inc. | C12: Hilot (Wellness Massage) NC II-MTP | D12: 45310 | E12: 45320 | F12: 45321 | G12: N/A | H12: N/A | I12: 45322 | J12: 45322
A13: Cebu | B13: Seabreeze Technical Education Training & Assessment Center Inc. | C13: Housekeeping NC II | D13: 45246 | E13: 45317 | F13: 45320 | G13: 45321 | H13: 45321 | I13: 45322 | J13: 45322
A14: Cebu | B14: Cebu Southwest Technical College, Inc. | C14: Shielded Metal Arc Welding (SMAW) NC I | D14: 45309 | E14: 45307 | F14: 45324 | G14: 45327 | H14: 45327 | I14: 45328 | J14: 45328
A15: Cebu | B15: Saint Homobonus Academy Inc. | C15: Contact Center Services NC II | D15: 45309 | E15: 45324 | F15: 45327 | G15: 45328 | H15: 45328 | I15: 46425 | J15: 45329
A16: Cebu | B16: Skillsbuild Training and Assessment Center, Corp | C16: Housekeeping NC II | D16: 45246 | E16: 45330 | F16: 45330 | G16: 45334 | H16: 45334 | I16: 45335 | J16: 45336
A17: Bohol | B17: Cloa Technical Institute | C17: Driving NC II | D17: 45019 | E17: 45331 | F17: 45334 | G17: 45335 | H17: 45335 | I17: 45336 | J17: 45336
A18: Bohol | B18: Cloa Technical Institute | C18: Driving (Articulated Vehicle) NC III | D18: 45019 | E18: 45331 | F18: 45334 | G18: 45335 | H18: 45335 | I18: 45336 | J18: 45336
A19: Bohol | B19: Cloa Technical Institute | C19: Heavy Equipment Operation (Rigid On-Highway Dump Truck) NC II | D19: 45019 | E19: 45331 | F19: 45334 | G19: 45335 | H19: 45335 | I19: 45336 | J19: 45336
A20: Bohol | B20: Cloa Technical Institute | C20: Heavy Equipment Operation (Transit Mixer) NC II | D20: 45019 | E20: 45331 | F20: 45334 | G20: 45335 | H20: 45335 | I20: 45336 | J20: 45336
A21: Cebu | B21: School of Knowledge for Industrial Labor, Leadership and Service Inc. | C21: Construction Painting NC II | D21: 44854 | E21: 45335 | F21: 45335 | G21: 45336 | H21: 45336 | I21: 45337 | J21: 45337
A22: Cebu | B22: School of Knowledge for Industrial Labor, Leadership and Service Inc. | C22: Emergency Medical Services NC II | D22: 44854 | E22: 45335 | F22: 45335 | G22: 45336 | H22: 45336 | I22: 45337 | J22: 45337
A23: Cebu | B23: School of Knowledge for Industrial Labor, Leadership and Service Inc. | C23: Masonry NC I | D23: 44854 | E23: 45335 | F23: 45335 | G23: 45336 | H23: 45336 | I23: 45337 | J23: 45337
A24: Negros Oriental | B24: Upfuture Technical Vocational Institute Inc. | C24: Scaffolding Works NC II (Supported Type Scaffold) | D24: 45215 | E24: 45327 | F24: 45336 | G24: 45336 | H24: 45336 | I24: 45337 | J24: 45338
A25: Negros Oriental | B25: Upfuture Technical Vocational Institute Inc. | C25: Electrical Installation and Maintenance NC II | D25: 45215 | E25: 45334 | F25: 45338 | G25: 45338 | H25: 45338 | I25: 45341 | J25: 45342
A26: Bohol | B26: Eastern Heights School of Excellence, Inc. | C26: Food and Beverage Services NC II-MTP | D26: 45030 | E26: 45323 | F26: 45341 | G26: N/A | H26: N/A | I26: 45342 | J26: 45343
A27: Cebu | B27: 3A Prime Hospitality Training and Assessment Center Inc.-Cebu City | C27: Bread and Pastry Production NC II-MTP | D27: 45030 | E27: 45347 | F27: 45341 | G27: N/A | H27: N/A | I27: 45342 | J27: 45343
A28: Cebu | B28: Provincial Training Center - Cebu (Daanbantayan) | C28: Trainers Methodology Level I (Trainer/Assessor) | D28: 44844 | E28: 45338 | F28: 45342 | G28: 45343 | H28: 45343 | I28: 45344 | J28: 45344
A29: Negros Oriental | B29: Armstrong Career and Technical Education Institute Inc. | C29: Organic Agriculture Production NC II | D29: 45139 | E29: 45330 | F29: 45343 | G29: 45343 | H29: 45343 | I29: 45344 | J29: 45345
A30: Bohol | B30: St. Pedro Calungsod College Inc. | C30: Electrical Installation and Maintenance NC II | D30: 44986 | E30: 45342 | F30: 45343 | G30: 45344 | H30: 45344 | I30: 45345 | J30: 45345
A31: Cebu | B31: Cebu Southwest Technical College Inc. | C31: Shielded Metal Arc Welding (SMAW) NC II-MTP | D31: 45030 | E31: 45344 | F31: 45345 | G31: N/A | H31: N/A | I31: 45348 | J31: 45349
A32: Cebu | B32: Metrologyx Training & Assessment Center Inc. | C32: Instrumentation and Control Servicing NC II-MTP | D32: 45303 | E32: 45330 | F32: 45349 | G32: N/A | H32: N/A | I32: 45350 | J32: 45351
A33: Cebu | B33: Metrologyx Training & Assessment Center Inc. | C33: Mechatronics Servicing NC II-MTP | D33: 45303 | E33: 45330 | F33: 45349 | G33: N/A | H33: N/A | I33: 45350 | J33: 45351
A34: Negros Oriental | B34: Upfuture Technical Vocational Institute Inc. | C34: Driving NC II | D34: 45215 | E34: 45344 | F34: 45349 | G34: 45350 | H34: 45350 | I34: 45351 | J34: 45351
A35: Bohol | B35: Provincial Training Center - Bilar | C35: Bread and Pastry Production NC II-MTP | D35: 45030 | E35: 45281 | F35: 45287 | G35: N/A | H35: N/A | I35: 45287 | J35: 45288
A36: Bohol | B36: Provincial Training Center - Bilar | C36: Cookery NC II-MTP | D36: 45030 | E36: 45281 | F36: 45287 | G36: N/A | H36: N/A | I36: 45287 | J36: 45288
A37: Bohol | B37: Provincial Training Center - Bilar | C37: Carpentry NC II-MTP | D37: 45030 | E37: 45281 | F37: 45287 | G37: N/A | H37: N/A | I37: 45287 | J37: 45288
A38: Cebu | B38: Hanas Training and Asssessment Center Incorporated | C38: Hilot (Wellness Massage) NC II | D38: 45309 | E38: 45352 | F38: 45352 | G38: 45355 | H38: 45355 | I38: 45356 | J38: 45356
A39: Cebu | B39: Hanas Training and Asssessment Center Incorporated | C39: Housekeeping NC II | D39: 45309 | E39: 45352 | F39: 45352 | G39: 45355 | H39: 45355 | I39: 45356 | J39: 45356
A40: Cebu | B40: R & K Watanabe Skills Training Institute Inc. | C40: Food and Beverage Services NC II | D40: 44706 | E40: 45322 | F40: 45355 | G40: 45356 | H40: 45356 | I40: 45357 | J40: 45357
...

Sheet 2025 F08
A1: PROVINCE | B1: Name of TVI/Company (a) | C1: Qualification Title (b) | D1: Conducts Orientation on Program Registration (c) | E1: Conducts Site Inspection and Submitts Site Inspection Report (d) | F1: Reviews and Evaluates Program Registration Application Documents (Day 1) (e) | G1: Prepares Recommendation and Submits Complete Documents to RO (Day 2) (f) | H1: Transmits the Application Documents, and Recommendations to RO (1-2 days) (g) | I1: Approved/Disapproves Program Registration Application Documents and Issues/Transmits CTPR/Letter of Denial (Day 3) (h) | J1: Transmits the CTPR and Complete Documents to Provincial Office/TVIs and conducts Post Orientation (1-2 days) (i) | K1: TOTAL NUMBER OF DAYS (3 DAYS) | L1: RO REMARKS
A2: Cebu | B2: Canetech Training and Assessment Center Inc. | C2: Hilot (Wellness Massage) NC II | D2: 45337 | E2: 45652 | F2: 45653 | G2: 45659 | H2: 45659 | I2: 45660 | J2: 45660
A3: Bohol | B3: CMC Institute of Business Management, Skills Training and Assessment Center Inc. | C3: Tourism Promotion Services NC II | D3: 45399 | E3: 45653 | F3: 45659 | G3: 45660 | H3: 45660 | I3: 45663 | J3: 45663
A4: Cebu | B4: Jacob Institute of Science and Technology Inc. | C4: Beauty Care (Nail Care) Services NC II | D4: 45463 | E4: 45663 | F4: 45664 | G4: 45665 | H4: 45665 | I4: 45666 | J4: 45666
A5: Cebu | B5: Jacob Institute of Science and Technology Inc. | C5: Hilot (Wellness Massage) NC II | D5: 45463 | E5: 45663 | F5: 45664 | G5: 45665 | H5: 45665 | I5: 45666 | J5: 45666
A6: Bohol | B6: TFK Elite 888 Corp. | C6: Organic Agriculture Production NC II | D6: 45491 | E6: 45667 | F6: 45670 | G6: 45671 | H6: 45671 | I6: 45672 | J6: 45672
A7: Cebu | B7: Sto. Niño Skills Development and Assessment Center Inc. | C7: Trainers Methodology Level I (Trainer/Assessor) | D7: 45575 | E7: 45668 | F7: 45670 | G7: 45671 | H7: 45671 | I7: 45672 | J7: 45672
A8: Cebu | B8: Arriba Technical Skills Training and Assessment Center Corp. | C8: Electrical Installation and Maintenance NC II-MTP | D8: 45636 | E8: 45672 | F8: 45672 | G8: N/A | H8: N/A | I8: 45673 | J8: 45674
A9: Negros Oriental | B9: Sto. Niño Skills Training & Assessment Center Incorporated | C9: Caregiving NC II-MTP | D9: 45040 | E9: 45652 | F9: 45673 | G9: N/A | H9: N/A | I9: 45674 | J9: 45677
A10: Bohol | B10: Collegio De Loboc | C10: Driving NC II | D10: 45615 | E10: 45674 | F10: 45677 | G10: 45678 | H10: 45678 | I10: 45679 | J10: 45679
A11: Cebu | B11: Regional Training Center - Cebu | C11: Digital Marketing Level III | D11: 45617 | E11: 45672 | F11: 45678 | G11: 45679 | H11: 45679 | I11: 45680 | J11: 45680
A12: Cebu | B12: Team AK English Inc. | C12: English as a Second Language Beginner (A1 and A2) Level | D12: 45518 | E12: 45680 | F12: 45687 | G12: 45688 | H12: 45688 | I12: 45691 | J12: 45691
A13: Siquijor | B13: Lazi Technical Institute | C13: Food and Beverage Services NC III | D13: 45659 | E13: 45666 | F13: 45692 | G13: 45692 | H13: 45692 | I13: 45693 | J13: 45694
A14: Cebu | B14: Uni Eco-Agri Farm Learning Institute, Inc. | C14: Organic Agriculture Production NC II-MTP | D14: 45645 | E14: 45695 | F14: 45698 | G14: N/A | H14: N/A | I14: 45699 | J14: 45700
A15: Cebu | B15: Sto. Niño Skills Development and Assessment Center Inc. | C15: Bread and Pastry Production NC II | D15: 45575 | E15: 45696 | F15: 45698 | G15: 45699 | H15: 45699 | I15: 45700 | J15: 45700
A16: Bohol | B16: Tagbilaran City College | C16: Events Management Services NC III | D16: 45546 | E16: 45699 | F16: 45700 | G16: 45701 | H16: 45701 | I16: 45702 | J16: 45702
A17: Cebu | B17: Crossxroad English Academy Corp. | C17: English as a Second Language Beginner (A1 and A2) Level | D17: 45568 | E17: 45700 | F17: 45700 | G17: 45701 | H17: 45701 | I17: 45336 | J17: 45336
A18: Negros Oriental | B18: Silliman University | C18: Agroentrepreneurship NC II | D18: 45572 | E18: 45701 | F18: 45701 | G18: 45702 | H18: 45702 | I18: 45705 | J18: 45705
A19: Negros Oriental | B19: Silliman University | C19: Trainers Methodology Level I (Trainer/Assessor) | D19: 45572 | E19: 45701 | F19: 45701 | G19: 45702 | H19: 45702 | I19: 45705 | J19: 45705
A20: Negros Oriental | B20: Silliman University | C20: Bookkeeping NC III | D20: 45572 | E20: 45701 | F20: 45702 | G20: 45705 | H20: 45705 | I20: 45706 | J20: 45706
A21: Cebu | B21: Saint Roch Institute Inc. | C21: Driving NC II | D21: 45649 | E21: 45706 | F21: 45707 | G21: 45707 | H21: 45707 | I21: 45708 | J21: 45709
A22: Cebu | B22: Saint Roch Institute Inc. | C22: Driving (Passenger Bus / Straight Truck) NC III | D22: 45649 | E22: 45706 | F22: 45707 | G22: 45707 | H22: 45707 | I22: 45708 | J22: 45709
A23: Cebu | B23: Zeo and Zoe Training and Assessment Center Inc. | C23: Shielded Metal Arc Welding (SMAW) NC I-MTP | D23: 45713 | E23: 45713 | F23: 45713 | G23: N/A | H23: N/A | I23: 45714 | J23: 45715
A24: Cebu | B24: Zeo and Zoe Training and Assessment Center Inc. | C24: Shielded Metal Arc Welding (SMAW) NC II-MTP | D24: 45713 | E24: 45713 | F24: 45713 | G24: N/A | H24: N/A | I24: 45714 | J24: 45715
A25: Cebu | B25: Can-Care Technical Vocational Education Training Assessment and Review Center Institute, Inc. | C25: Caregiving NC II | D25: 45568 | E25: 45694 | F25: 45713 | G25: 45714 | H25: 45714 | I25: 45715 | J25: 45715
A26: Negros Oriental | B26: Silliman University Farm | C26: Agroentrepreneurship NC II | D26: 45642 | E26: 45712 | F26: 45713 | G26: 45714 | H26: 45714 | I26: 45715 | J26: 45715
A27: Negros Oriental | B27: Silliman University Farm | C27: Animal Production (Poultry-Chicken) NC II | D27: 45642 | E27: 45712 | F27: 45713 | G27: 45714 | H27: 45714 | I27: 45715 | J27: 45715
A28: Negros Oriental | B28: Silliman University | C28: Events Management Services NC III | D28: 45642 | E28: 45712 | F28: 45713 | G28: 45714 | H28: 45714 | I28: 45715 | J28: 45715
A29: Cebu | B29: SMEA-AG Global Education Inc. | C29: English as a Second Language Beginner (A1 and A2) Level | D29: 45518 | E29: 45709 | F29: 45715 | G29: 45716 | H29: 45716 | I29: 45719 | J29: 45719
A30: Negros Oriental | B30: Silliman University Farm | C30: Animal Production (Swine) NC II | D30: 45642 | E30: 45713 | F30: 45715 | G30: 45716 | H30: 45716 | I30: 45719 | J30: 45719
A31: Negros Oriental | B31: Silliman University Farm | C31: Animal Production (Ruminants) NC II | D31: 45642 | E31: 45713 | F31: 45715 | G31: 45716 | H31: 45716 | I31: 45719 | J31: 45719
A32: Negros Oriental | B32: Silliman University Farm | C32: Organic Agriculture Production NC II | D32: 45642 | E32: 45713 | F32: 45715 | G32: 45716 | H32: 45716 | I32: 45719 | J32: 45719
A33: Cebu | B33: Skillsbuild Training and Assessment Center Corp. | C33: Housekeeping NC II-MTP | D33: 45699 | E33: 45716 | F33: 45719 | G33: N/A | H33: N/A | I33: 45720 | J33: 45721
A34: Bohol | B34: IWH Bohol Resort Corp. Doing Business Under the Name and Style of Best Western Plus the Ivywall Resort, Panglao | C34: Develop and Food Safety Program (Leading to Food Production (Professional Cookery) NC IV | D34: 45695 | E34: 45715 | F34: 45716 | G34: 45719 | H34: 45719 | I34: 45720 | J34: 45720 | M34: Industry
A35: Cebu | B35: Happy Learning Academy, Inc. | C35: English as a Second Language Intermediate (B1 and B2) Level | D35: 45518 | E35: 45720 | F35: 45720 | G35: 45721 | H35: 45721 | I35: 45722 | J35: 45722
A36: Cebu | B36: HNSA-TVET and Assessment Center Inc. | C36: Housekeeping NC II-MTP | D36: 45699 | E36: 45716 | F36: 45722 | G36: N/A | H36: N/A | I36: 45723 | J36: 45724
A37: Cebu | B37: JRJ Solution Enterprise | C37: Computer Security Incident Handling Level I | D37: 45708 | E37: 45721 | F37: 45721 | G37: 45722 | H37: 45722 | I37: 45723 | J37: 45723 | M37: Industry
A38: Cebu | B38: JRJ Solution Enterprise | C38: Cyber Riks Assessment Level III | D38: 45708 | E38: 45721 | F38: 45721 | G38: 45722 | H38: 45722 | I38: 45723 | J38: 45723 | M38: Industry
A39: Cebu | B39: JRJ Solution Enterprise | C39: Cyber Threat Mitigation Level II | D39: 45708 | E39: 45721 | F39: 45721 | G39: 45722 | H39: 45722 | I39: 45723 | J39: 45723 | M39: Industry
A40: Cebu | B40: JRJ Solution Enterprise | C40: Cyber Threat Intelligence Analysis Level III | D40: 45708 | E40: 45721 | F40: 45721 | G40: 45722 | H40: 45722 | I40: 45723 | J40: 45723 | M40: Industry
...

Sheet NEW 2025 F08
A1: Province | B1: Name of Applicant Institution (a) | C1: Qualification Title (b) | D1: Conducts Orientation to Applicant Institution/ Prospective Institution (c) | E1: Reviews and Check Program Registration Application Documents and Provision of Feedback to Applicant Institution (d) | F1: Conducts of Ocular Inspection/ Visitation and Preparation and Submission of Inspection Report (e) | G1: Conducts Evaluation of the completeness, correctness and validity of all program registration application documents (Day 1) (f) | H1: Prepares Recommendation and Submits Complete Documents to RO (Day 2) (g) | I1: Transmits the Application Documents, and Recommendations to RO (1-2 days) (h) | J1: Approves and Issuances of CTPR (Day 3) (i) | K1: Transmits approved documents and CTPR to applicant institution through PO/DO (1-2 days) (j) | L1: TOTAL NUMBER OF DAYS (3 DAYS) | M1: RO REMARKS
A2: Cebu | B2: Sidlakan Training Center Inc. | C2: Housekeeping NC II | D2: 45708 | F2: 45859 | G2: 45902 | H2: 45903 | I2: 45903 | J2: 45904 | K2: 45904
A3: Cebu | B3: EliteCraft Education Corp. | C3: Telecom OSP Installation (Fiber Optic Cable) NC II | D3: 45889 | E3: 45889 | F3: 45903 | G3: 45903 | H3: 45904 | I3: 45904 | J3: 45905 | K3: 45905
A4: Cebu | B4: St. Cecilia's College - Cebu, Inc. | C4: Driving NC II | D4: 45889 | E4: 45889 | F4: 45904 | G4: 45905 | H4: 45908 | I4: 45908 | J4: 45910 | K4: 45910
A5: Cebu | B5: St. Cecilia's College - Cebu, Inc. | C5: Electrical Installation and Maintenance NC II | D5: 45889 | E5: 45889 | F5: 45904 | G5: 45905 | H5: 45908 | I5: 45908 | J5: 45910 | K5: 45910
A6: Cebu | B6: Global Power Skills Development Center Inc. | C6: Housekeeping NC II-MTP | D6: 45051 | E6: 45860 | F6: 45884 | G6: 45911 | H6: N/A | I6: N/A | J6: 45912 | K6: 45915
A7: Cebu | B7: Cella English Academy Inc. | C7: English as as Second Language Beginner (A1 and A2) Level | D7: 45898 | E7: 45901 | F7: 45910 | G7: 45911 | H7: 45912 | I7: 45912 | J7: 45915 | K7: 45915
A8: Cebu | B8: Worldwide ESL Tutorial Academy Corp | C8: English as as Second Language Beginner (A1 and A2) Level | D8: 45898 | E8: 45901 | F8: 45910 | G8: 45911 | H8: 45912 | I8: 45912 | J8: 45915 | K8: 45915
A9: Cebu | B9: Balamban Extensive Skills Technology Inc. | C9: Agricultural Crops Production NC II | D9: 45889 | E9: 45908 | F9: 45912 | G9: 45915 | H9: 45916 | I9: 45916 | J9: 45917 | K9: 45917
A10: Cebu | B10: Balamban Extensive Skills Technology Inc. | C10: Computer Systems Servicing NC II | D10: 45889 | E10: 45908 | F10: 45912 | G10: 45915 | H10: 45916 | I10: 45916 | J10: 45917 | K10: 45917
A11: Cebu | B11: Balamban Extensive Skills Technology Inc. | C11: Dressmaking NC II | D11: 45889 | E11: 45908 | F11: 45912 | G11: 45915 | H11: 45916 | I11: 45916 | J11: 45917 | K11: 45917
A12: Cebu | B12: Opportunities Today Training and Assessment Center Inc. | C12: Bread and Pastry Production NC II-MTP | D12: 45589 | E12: 45889 | F12: 45917 | G12: 45917 | H12: N/A | I12: N/A | J12: 45918 | K12: 45919
A13: Cebu | B13: Opportunities Today Training and Assessment Center Inc. | C13: Cookery NC II-MTP | D13: 45589 | E13: 45889 | F13: 45917 | G13: 45917 | H13: N/A | I13: N/A | J13: 45918 | K13: 45919
A14: Cebu | B14: Dew Pima Training and Assessment Center | C14: Computer Systems Servicing NC II-MTP | D14: 45589 | E14: 45887 | F14: 45917 | G14: 45919 | H14: N/A | I14: N/A | J14: 45922 | K14: 45923
A15: Cebu | B15: GFG Assessment & Training Center Corp. | C15: Computer Systems Servicing NC II | D15: 45898 | E15: 45916 | F15: 45917 | G15: 45918 | H15: 45918 | I15: 45918 | J15: 45922 | K15: 45923
A16: Cebu | B16: GFG Assessment & Training Center Corp. | C16: Content Creation (Social Media) Level III | D16: 45898 | E16: 45916 | F16: 45917 | G16: 45918 | H16: 45918 | I16: 45918 | J16: 45922 | K16: 45923
A17: Cebu | B17: GFG Assessment & Training Center Corp. | C17: Cyber Threat Monitoring Level I | D17: 45898 | E17: 45916 | F17: 45917 | G17: 45918 | H17: 45918 | I17: 45918 | J17: 45922 | K17: 45923
A18: Cebu | B18: GFG Assessment & Training Center Corp. | C18: Data Analytics Level III | D18: 45898 | E18: 45916 | F18: 45917 | G18: 45918 | H18: 45918 | I18: 45918 | J18: 45922 | K18: 45923
A19: Cebu | B19: Opportunities Today Training and Assessment Center Inc. | C19: Computer Systems Servicing NC II | D19: 45889 | E19: 45908 | F19: 45922 | G19: 45923 | H19: 45924 | I19: 45924 | J19: 45925 | K19: 45925
A20: Negros Oriental | B20: RAMS Art Training and Assessment Center Inc. | C20: Bread and Pastry Production NC II-MTP | D20: 45040 | E20: 45881 | F20: 45912 | G20: 45926 | H20: N/A | I20: N/A | J20: 45929 | K20: 45930
A21: Negros Oriental | B21: RAMS Art Training and Assessment Center Inc. | C21: Bookkeeping NC III-MTP | D21: 45040 | E21: 45881 | F21: 45912 | G21: 45926 | H21: N/A | I21: N/A | J21: 45929 | K21: 45930
A22: Negros Oriental | B22: RAMS Art Training and Assessment Center Inc. | C22: Electrical Installation and Maintenance NC II-MTP | D22: 45040 | E22: 45881 | F22: 45912 | G22: 45926 | H22: N/A | I22: N/A | J22: 45929 | K22: 45930
A23: Cebu | B23: R & K Watanabe Skills Training Institute Inc. | C23: Food and Beverage Services NC II-MTP | D23: 45839 | E23: 45876 | F23: 45932 | G23: 45932 | H23: N/A | I23: N/A | J23: 45933 | K23: 45936
A24: Cebu | B24: Green International Technological College, Inc. doing business under the name and style of Green International Technological College | C24: English as a Second Language Beginner (A1 and A2) Level | D24: 45898 | E24: 45923 | F24: 45931 | G24: 45933 | H24: 45934 | I24: 45934 | J24: 45936 | K24: 45936
A25: Cebu | B25: N Blessing Infinite Education and Development Inc. | C25: Coconut Production Level II | D25: 45918 | E25: 45933 | F25: 45937 | G25: 45938 | H25: 45939 | I25: 45939 | J25: 45940 | K25: 45940
A26: Cebu | B26: KLN Skills & Management Training and Assessment Center, Inc. | C26: Computer Systems Servicing NC II | D26: 45898 | E26: 45937 | F26: 45938 | G26: 45939 | H26: 45940 | I26: 45940 | J26: 45943 | K26: 45943
